Workbook

Sheet DCF
B2: APPLE DCF
B4: Ticker | C4: AAPL | E4: Implied Share Price | F4: =L80 -> 246.70244
B5: Year End | C5: 46291 | E5: Current Share Price | F5: =334.8 -> 334.8
E6: Implied Gain / Loss | F6: =F4/F5-1 -> -0.26313487
B8: Assumptions
B9: Switches | E9: Conservative | H9: Street/Base | K9: Optimistic
B10: Revenue | C10: 2 | E10: Revenue '27-'28 | F10: 0.8 | K10: Revenue '27-'28 | L10: 1.2
B11: EBIT | C11: 2 | E11: Revenue 2031 | F11: 0.02 | H11: Revenue 2031 | I11: 0.05 | K11: Revenue 2031 | L11: 0.08
B12: WACC | C12: 3 | E12: EBIT '27-'28 | F12: 0.9 | K12: EBIT '27-'28 | L12: 1.1
B13: TGR | C13: 2
H14: Taxes | I14: 0.165
B15: WACC | C15: =CHOOSE($C$12,F15,I15,L15) -> 0.075 | E15: WACC | F15: =I15+0.5% -> 0.09905203 | H15: WACC | I15: =WACC!E22 -> 0.09405203 | K15: WACC | L15: 0.075
B16: TGR | C16: =CHOOSE($C$13,F16,I16,L16) -> 0.025 | E16: TGR | F16: 0.02 | H16: TGR | I16: 0.025 | K16: TGR | L16: 0.03
B18: Income Statement | D18: 2023 | E18: 2024 | F18: 2025 | G18: 2026E | H18: 2027E | I18: 2028E | J18: 2029E | K18: 2030E | L18: 2031E
B19: Revenue | D19: ='Income Statement'!D4 -> 383285 | E19: ='Income Statement'!C4 -> 391035 | F19: ='Income Statement'!B4 -> 416161 | G19: =Estimates!B20 -> 477833 | H19: =Estimates!C20 -> 527946 | I19: =Estimates!D20 -> 571023 | J19: =Estimates!E20 -> 608140 | K19: =Estimates!F20 -> 638547 | L19: =Estimates!G20 -> 664089
B20: % Growth | D20: - | E20: =E19/D19-1 -> 0.020219941 | F20: =F19/E19-1 -> 0.064255118 | G20: =G19/F19-1 -> 0.14819265 | H20: =H19/G19-1 -> 0.10487555 | I20: =I19/H19-1 -> 0.081593572 | J20: =J19/I19-1 -> 0.065000884 | K20: =K19/J19-1 -> 0.05 | L20: =L19/K19-1 -> 0.040000188
B22: EBIT | D22: ='Income Statement'!D11 -> 114301 | E22: ='Income Statement'!C11 -> 123216 | F22: ='Income Statement'!B11 -> 133050 | G22: =Estimates!B24 -> 156384 | H22: =Estimates!C24 -> 166731 | I22: =Estimates!D24 -> 186085 | J22: =Estimates!E24 -> 198193 | K22: =Estimates!F24 -> 208109 | L22: =Estimates!G24 -> 216447
B23: % of Sales | D23: =D22/D19 -> 0.29821412 | E23: =E22/E19 -> 0.31510223 | F23: =F22/F19 -> 0.319708 | G23: =G22/G19 -> 0.32727752 | H23: =H22/H19 -> 0.31581071 | I23: =I22/I19 -> 0.32588004 | J23: =J22/J19 -> 0.32590029 | K23: =K22/K19 -> 0.32591023 | L23: =L22/L19 -> 0.32593071
B25: Taxes | D25: ='Income Statement'!D14 -> 16741 | E25: ='Income Statement'!C14 -> 29749 | F25: ='Income Statement'!B14 -> 20719
B26: % of Sales | D26: =D25/D19 -> 0.043677681 | E26: =E25/E19 -> 0.076077589 | F26: =F25/F19 -> 0.04978602
B28: Cash Flow Items | D28: 2023 | E28: 2024 | F28: 2025 | G28: =F28+1 -> 2026 | H28: =G28+1 -> 2027 | I28: =H28+1 -> 2028 | J28: 2029 | K28: 2030 | L28: 2031
B29: D&A | D29: ='Cash Flow'!F14 -> 11519 | E29: ='Cash Flow'!D14 -> 11445 | F29: ='Cash Flow'!B14 -> 11698
B30: % of Sales | D30: =D29/D19 -> 0.030053355 | E30: =E29/E19 -> 0.02926848 | F30: =F29/F19 -> 0.028109313
B32: CapEx | D32: 10959 | E32: 9447 | F32: 12715
B33: % of Sales | D33: =D32/D19 -> 0.028592301 | E33: =E32/E19 -> 0.024158963 | F33: =F32/F19 -> 0.030553079
B35: Change in NWC | D35: ='Cash Flow'!I17 -> -5577 | E35: ='Cash Flow'!H17 -> 3651 | F35: ='Cash Flow'!G17 -> -24900
B36: % of Sales | D36: =D35/D19 -> -0.01455053 | E36: =E35/E19 -> 0.0093367601 | F36: =F35/F19 -> -0.059832613
B37: % of Changes in Sales | E37: =E35/(E19-D19) -> 0.47109677 | F37: =F35/(F19-E19) -> -0.99100533
G38: 1 | H38: 2 | I38: 3 | J38: 4 | K38: 5 | L38: 6
B39: DCF | D39: 2023 | E39: 2024 | F39: 2025 | G39: =F39+1 -> 2026 | H39: =G39+1 -> 2027 | I39: =H39+1 -> 2028 | J39: 2029 | K39: 2030 | L39: 2031
B40: Revenue | D40: =D19 -> 383285 | E40: =E19 -> 391035 | F40: =F19 -> 416161 | G40: =F40*(1+G41) -> 477833 | H40: =G40*(1+H41) -> 527946 | I40: =H40*(1+I41) -> 571023 | J40: =I40*(1+J41) -> 611601.25 | K40: =J40*(1+K41) -> 648622.21 | L40: =K40*(1+L41) -> 681053.32
B41: % Growth | D41: - | E41: =E40/D40-1 -> 0.020219941 | F41: =F40/E40-1 -> 0.064255118 | G41: =OFFSET(G41,$C$10,0) -> 0.14819265 | H41: =OFFSET(H41,$C$10,0) -> 0.10487555 | I41: =OFFSET(I41,$C$10,0) -> 0.081593572 | J41: =OFFSET(J41,$C$10,0) -> 0.071062381 | K41: =OFFSET(K41,$C$10,0) -> 0.060531191 | L41: =OFFSET(L41,$C$10,0) -> 0.05
B42: Conservative Case | G42: =G43 -> 0.14819265 | H42: =H43*$F$10 -> 0.083900442 | I42: =I43*$F$10 -> 0.065274858 | J42: =I42-($I$42-$L$42)/($L$39-$I$39) -> 0.050183238 | K42: =J42-($I$42-$L$42)/($L$39-$I$39) -> 0.035091619 | L42: =F11 -> 0.02
B43: Street Case | G43: =G20 -> 0.14819265 | H43: =H20 -> 0.10487555 | I43: =I20 -> 0.081593572 | J43: =I43-($I$43-$L$43)/($L$39-$I$39) -> 0.071062381 | K43: =J43-($I$43-$L$43)/($L$39-$I$39) -> 0.060531191 | L43: =I11 -> 0.05
B44: Optimistic Case | G44: =G43 -> 0.14819265 | H44: =H43*$L$10 -> 0.12585066 | I44: =I43*$L$10 -> 0.097912286 | J44: =I44-($I$44-$L$44)/($L$39-$I$39) -> 0.091941524 | K44: =J44-($I$44-$L$44)/($L$39-$I$39) -> 0.085970762 | L44: =L11 -> 0.08
B46: EBIT | D46: =D22 -> 114301 | E46: =E22 -> 123216 | F46: =F22 -> 133050 | G46: =G47*G40 -> 156384 | H46: =H47*H40 -> 166731 | I46: =I47*I40 -> 186085 | J46: =J47*J40 -> 199308.64 | K46: =K47*K40 -> 211373.03 | L46: =L47*L40 -> 221941.68
B47: % of Sales | D47: =D23 -> 0.29821412 | E47: =E23 -> 0.31510223 | F47: =F23 -> 0.319708 | G47: =OFFSET(G47,$C$11,0) -> 0.32727752 | H47: =OFFSET(H47,$C$11,0) -> 0.31581071 | I47: =OFFSET(I47,$C$11,0) -> 0.32588004 | J47: =OFFSET(J47,$C$11,0) -> 0.32588004 | K47: =OFFSET(K47,$C$11,0) -> 0.32588004 | L47: =OFFSET(L47,$C$11,0) -> 0.32588004
B48: Conservative Case | G48: =G49 -> 0.32727752 | H48: =H49*$F$12 -> 0.28422964 | I48: =I49*$F$12 -> 0.29329204 | J48: =J49*$F$12 -> 0.29329204 | K48: =K49*$F$12 -> 0.29329204 | L48: =L49*$F$12 -> 0.29329204
B49: Street Case | G49: =G23 -> 0.32727752 | H49: =H23 -> 0.31581071 | I49: =I23 -> 0.32588004 | J49: =I49 -> 0.32588004 | K49: =J49 -> 0.32588004 | L49: =K49 -> 0.32588004
B50: Optimistic Case | G50: =G49 -> 0.32727752 | H50: =H49*$L$12 -> 0.34739178 | I50: =I49*$L$12 -> 0.35846805 | J50: =J49*$L$12 -> 0.35846805 | K50: =K49*$L$12 -> 0.35846805 | L50: =L49*$L$12 -> 0.35846805
...

Sheet Income Statement
A1: CONSOLIDATED STATEMENTS OF OPERATIONS - USD ($) | B1: 12 Months Ended
A2: shares in Thousands, $ in Millions
B3: Sep. 27, 2025 | C3: Sep. 28, 2024 | D3: Sep. 30, 2023
A4: Net sales | B4: 416161 | C4: 391035 | D4: 383285
A5: Cost of sales | B5: 220960 | C5: 210352 | D5: 214137
A6: Gross margin | B6: 195201 | C6: 180683 | D6: 169148
A7: Operating expenses:
A8: Research and development | B8: 34550 | C8: 31370 | D8: 29915
A9: Selling, general and administrative | B9: 27601 | C9: 26097 | D9: 24932
A10: Total operating expenses | B10: 62151 | C10: 57467 | D10: 54847
A11: Operating income | B11: 133050 | C11: 123216 | D11: 114301
A12: Other income/(expense), net | B12: -321 | C12: 269 | D12: -565
A13: Income before provision for income taxes | B13: 132729 | C13: 123485 | D13: 113736
A14: Provision for income taxes | B14: 20719 | C14: 29749 | D14: 16741
A15: Net income | B15: $ 112,010 | C15: $ 93,736 | D15: $ 96,995
A16: Earnings per share:
A17: Basic (in dollars per share) | B17: $ 7.49 | C17: $ 6.11 | D17: $ 6.16
A18: Diluted (in dollars per share) | B18: $ 7.46 | C18: $ 6.08 | D18: $ 6.13

Sheet Balance Sheet
A1: Apple Inc.
A2: CONSOLIDATED BALANCE SHEETS
A3: (In millions, except number of shares, which are reflected in thousands, and par value)
B6: September 27, 2025 | D6: September 28, 2024
A8: ASSETS:
A9: Current assets:
A10: Cash and cash equivalents | B10: 35,934 | D10: 29,943
A11: Marketable securities | B11: 18,763 | D11: 35,228
A12: Accounts receivable, net | B12: 39,777 | D12: 33,410
A13: Vendor non-trade receivables | B13: 33,180 | D13: 32,833
A14: Inventories | B14: 5,718 | D14: 7,286
A15: Other current assets | B15: 14,585 | D15: 14,287
A16: Total current assets | B16: 147,957 | D16: 152,987
A18: Non-current assets:
A19: Marketable securities | B19: 77,723 | D19: 91,479
A20: Property, plant and equipment, net | B20: 49,834 | D20: 45,680
A21: Other non-current assets | B21: 83,727 | D21: 74,834
A22: Total non-current assets | B22: 211,284 | D22: 211,993
A23: Total assets | B23: 359,241 | D23: 364,980
A25: LIABILITIES AND SHAREHOLDERS’ EQUITY:
A26: Current liabilities:
A27: Accounts payable | B27: 69,860 | D27: 68,960
A28: Other current liabilities | B28: 66,387 | D28: 78,304
A29: Deferred revenue | B29: 9,055 | D29: 8,249
A30: Commercial paper | B30: 7,979 | D30: 9,967
A31: Term debt | B31: 12,350 | D31: 10,912
A32: Total current liabilities | B32: 165,631 | D32: 176,392
A34: Non-current liabilities:
A35: Term debt | B35: 78,328 | D35: 85,750
A36: Other non-current liabilities | B36: 41,549 | D36: 45,888
A37: Total non-current liabilities | B37: 119,877 | D37: 131,638
A38: Total liabilities | B38: 285,508 | D38: 308,030
A40: Commitments and contingencies
A42: Shareholders’ equity:
A43: Common stock and additional paid-in capital, $0.00001 par value: 50,400,000 shares authorized; 14,773,260 and 15,116,786 shares issued and outstanding, respectively | B43: 93,568 | D43: 83,276
A44: Accumulated deficit | B44: -14264 | D44: -19154
A45: Accumulated other comprehensive loss | B45: -5571 | D45: -7172
A46: Total shareholders’ equity | B46: 73,733 | D46: 56,950
A47: Total liabilities and shareholders’ equity | B47: 359,241 | D47: 364,980

Sheet Cash Flow
A2: Apple Inc.
A3: CONSOLIDATED STATEMENTS OF CASH FLOWS
A4: (In millions)
B6: Years ended
B7: September 27, | D7: September 28, | F7: September 30,
B8: 2025 | D8: 2024 | F8: 2023
A9: Cash, cash equivalents, and restricted cash and cash equivalents, beginning balances | B9: 29,943 | D9: 30,737 | F9: 24,977
A11: Operating activities:
A12: Net income | B12: 112,010 | D12: 93,736 | F12: 96,995
A13: Adjustments to reconcile net income to cash generated by operating activities:
A14: Depreciation and amortization | B14: 11698 | D14: 11445 | F14: 11519
A15: Share-based compensation expense | B15: 12,863 | D15: 11,688 | F15: 10,833
A16: Other | B16: -89 | D16: -2266 | F16: -2227
A17: Changes in operating assets and liabilities: | G17: -24900 | H17: 3651 | I17: -5577
A18: Accounts receivable, net | B18: -6682 | D18: -3788 | F18: -1688
A19: Vendor non-trade receivables | B19: -347 | D19: -1356 | F19: 1,271
A20: Inventories | B20: 1,400 | D20: -1046 | F20: -1618
A21: Other current and non-current assets | B21: -9197 | D21: -11731 | F21: -5684
A22: Accounts payable | B22: 902 | D22: 6,020 | F22: -1889
A23: Other current and non-current liabilities | B23: -11076 | D23: 15,552 | F23: 3,031
A24: Cash generated by operating activities | B24: 111,482 | D24: 118,254 | F24: 110,543
A26: Investing activities:
A27: Purchases of marketable securities | B27: -24407 | D27: -48656 | F27: -29513
A28: Proceeds from maturities of marketable securities | B28: 40,907 | D28: 51,211 | F28: 39,686
A29: Proceeds from sales of marketable securities | B29: 12,890 | D29: 11,135 | F29: 5,828
A30: Payments for acquisition of property, plant and equipment | B30: -12715 | D30: -9447 | F30: -10959
A32: Other | B32: -1480 | D32: -1308 | F32: -1337
A33: Cash generated by investing activities | B33: 15,195 | D33: 2,935 | F33: 3,705
A35: Financing activities:
A36: Payments for taxes related to net share settlement of equity awards | B36: -5960 | D36: -5441 | F36: -5431
A37: Payments for dividends and dividend equivalents | B37: -15421 | D37: -15234 | F37: -15025
A38: Repurchases of common stock | B38: -90711 | D38: -94949 | F38: -77550
A39: Proceeds from issuance of term debt, net | B39: 4,481 | D39: — | F39: 5,228
A40: Repayments of term debt | B40: -10932 | D40: -9958 | F40: -11151
A41: Proceeds from/(Repayments of) commercial paper, net | B41: -2032 | D41: 3,960 | F41: -3978
A42: Other | B42: -111 | D42: -361 | F42: -581
A43: Cash used in financing activities | B43: -120686 | D43: -121983 | F43: -108488
A45: Increase/(Decrease) in cash, cash equivalents, and restricted cash and cash equivalents | B45: 5,991 | D45: -794 | F45: 5,760
A46: Cash, cash equivalents, and restricted cash and cash equivalents, ending balances | B46: 35,934 | D46: 29,943 | F46: 30,737
A48: Supplemental cash flow disclosure:
...

Sheet Estimates
A1: Fiscal Period: September | B1: 2021 | C1: 2022 | D1: 2023 | E1: 2024 | F1: 2025 | G1: 2026 | H1: 2027 | I1: 2028
A3: Net sales 1 | B3: 365817 | C3: 394328 | D3: 383285 | E3: 391035 | F3: 416161 | G3: 477833 | H3: 527946 | I3: 571023
A4: Change | B4: - | C4: 0.0779 | D4: -0.028 | E4: 0.0202 | F4: 0.0643 | G4: 0.1482 | H4: 0.1049 | I4: 0.0816
A5: EBITDA 1 | B5: 120233 | C5: 130541 | D5: 125820 | E5: 134661 | F5: 144495 | G5: 169437 | H5: 180100 | I5: 198544
A6: Change | B6: - | C6: 0.0857 | D6: -0.0362 | E6: 0.0703 | F6: 0.073 | G6: 0.1726 | H6: 0.0629 | I6: 0.1024
A7: EBIT 1 | B7: 108949 | C7: 119437 | D7: 114301 | E7: 123216 | F7: 133050 | G7: 156384 | H7: 166731 | I7: 186085
A8: Change | B8: - | C8: 0.0963 | D8: -0.043 | E8: 0.078 | F8: 0.0798 | G8: 0.1754 | H8: 0.0662 | I8: 0.1161
A9: Interest Paid 1 | B9: -2645 | C9: -334 | D9: -565 | E9: 269 | F9: -321 | G9: -402 | H9: -1000 | I9: -1000
A10: Earnings before Tax (EBT) 1 | B10: 109207 | C10: 119103 | D10: 113736 | E10: 123485 | F10: 132729 | G10: 156719 | H10: 165810 | I10: 184938
A11: Change | B11: - | C11: 0.0906 | D11: -0.0451 | E11: 0.0857 | F11: 0.0749 | G11: 0.1807 | H11: 0.058 | I11: 0.1154
A12: Net income 1 | B12: 94680 | C12: 99803 | D12: 96995 | E12: 93736 | F12: 112010 | G12: 129933 | H12: 138582 | I12: 154136
A13: Change | B13: - | C13: 0.0541 | D13: -0.0281 | E13: -0.0336 | F13: 0.195 | G13: 0.16 | H13: 0.0666 | I13: 0.1122
A16: https://www.marketscreener.com/quote/stock/APPLE-INC-126415778/finances/
B19: 2026 | C19: 2027 | D19: 2028 | E19: 2029 | F19: 2030 | G19: 2031
A20: Net sales | B20: 477833 | C20: 527946 | D20: 571023 | E20: 608140 | F20: 638547 | G20: 664089
A21: Change | B21: 0.1482 | C21: 0.1049 | D21: 0.0816 | E21: 0.065 | F21: 0.05 | G21: 0.04
A22: EBITDA | B22: 169437 | C22: 180100 | D22: 198544 | E22: 211470 | F22: 222033 | G22: 230899
A23: Change | B23: 0.1726 | C23: 0.0629 | D23: 0.1024 | E23: 0.0651 | F23: 0.05 | G23: 0.0399
A24: EBIT | B24: 156384 | C24: 166731 | D24: 186085 | E24: 198193 | F24: 208109 | G24: 216447
A25: Change | B25: 0.1754 | C25: 0.0662 | D25: 0.1161 | E25: 0.0651 | F25: 0.05 | G25: 0.0401
A26: Interest Paid | B26: -402 | C26: -1000 | D26: -1000 | E26: -1000 | F26: -1000 | G26: -1000
A27: Earnings before Tax (EBT) | B27: 156719 | C27: 165810 | D27: 184938 | E27: 197193 | F27: 207109 | G27: 215447
A28: Change | B28: 0.1807 | C28: 0.058 | D28: 0.1154 | E28: 0.0663 | F28: 0.0503 | G28: 0.0403
A29: Net income | B29: 129933 | C29: 138582 | D29: 154136 | E29: 164138 | F29: 172346 | G29: 179238
A30: Change | B30: 0.16 | C30: 0.0666 | D30: 0.1122 | E30: 0.0649 | F30: 0.05 | G30: 0.04

Sheet WACC
B2: WACC
B3: Units: $ in millions, except percentages and beta
B4: WACC = % of equity x cost of equity + % of debt x cost of debt x (1- Tax Rate)
B5: Cost of equity = Risk free rate + Beta x Market Risk Premium
B7: WACC
B8: Market Cap ($mm) | E8: 4980000
B9: % of Equity | E9: =E8/(E8+E15) -> 0.98211718
B10: Cost of Equity | E10: =E11+E12*E13 -> 0.095126
B11: Risk Free Rate | E11: 0.05
B12: Beta | E12: 1.09
B13: Market Risk Premium | E13: 0.0414
B15: Debt ($mm) | E15: =12350+78328 -> 90678
B16: % of Debt | E16: =E15/(E8+E15) -> 0.017882816
B17: Cost of Debt | E17: 0.042
B18: Tax Rate | E18: =DCF!I14 -> 0.165
B20: Total Capital ($mm) | E20: =E8+E15 -> 5070678
B22: WACC | E22: =E9*E10+E16*E17*(1-E18) -> 0.09405203
